Workbook

Sheet tagging
A1: Podcast Subject | B1: Electrode | C1: Full Name | D1: Peak Time | E1: Peak Value | F1: NYU Subject | G1: Location | H1: Stream | I1: position in stream | J1: confidence | K1: comments | L1: general comments
A2: sub-02 | B2: EEGPO_02REF | C2: 662_EEGPO_02REF | D2: 0.2 | E2: 0.35706693 | F2: 662 | L2: position in stream scored from 1-7 in dorsal/ventral 8-10 after convergence and before motor strip. 15 is outside expected areas
A3: sub-03 | B3: LGA10 | C3: 717_LGA10 | D3: 0.3 | E3: 0.55398136 | F3: 717 | G3: IFG Broca | H3: M | I3: 6 | K3: borderline MFG | L3: locatio = gyrus/sulcus, with a/m/g for anterior/middle/posterior respectively
A4: sub-03 | B4: LGA18 | C4: 717_LGA18 | D4: 0.45 | E4: 0.13539311 | F4: 717 | G4: IFG Broca | H4: M | I4: 6 | K4: pars orbitalis | L4: stream - either PA - primary auditory (before divergence), V - ventral, D - dorsal, M - merge (IFG) and PM - post merge (between broca/insula and primary motor cortex)
A5: sub-03 | B5: LGA27 | C5: 717_LGA27 | D5: 0.35 | E5: 0.22995235 | F5: 717 | G5: IFG Broca/ aSTG | H5: M/V | I5: 46176 | K5: on the sylvian fissure in the coronal, in the axial a little more STG
A6: sub-03 | B6: LGA32 | C6: 717_LGA32 | D6: -0.85 | E6: 0.10465358 | F6: 717 | G6: Something's wrong, looks extra-axial
A7: sub-03 | B7: LGA36 | C7: 717_LGA36 | D7: 0.8 | E7: 0.1767367 | F7: 717 | G7: aSTG/STS | H7: V | I7: 3
A8: sub-03 | B8: LGA37 | C8: 717_LGA37 | D8: 0 | E8: 0.38984398 | F8: 717 | G8: aSTG | H8: V | I8: 3
A9: sub-03 | B9: LGA38 | C9: 717_LGA38 | D9: 0.18 | E9: 0.33650977 | F9: 717 | G9: mSTG | H9: PA/V | I9: 46024 | K9: Borderline too far outside of brain
A10: sub-03 | B10: LGA39 | C10: 717_LGA39 | D10: 0.12 | E10: 0.19198058 | F10: 717 | G10: m/pSTG | H10: PA | I10: 1 | K10: Outside of the brain
A11: sub-03 | B11: LGA4 | C11: 717_LGA4 | D11: 0.68 | E11: 0.14526286 | F11: 717 | G11: MFG | H11: PM | I11: 8 | K11: possibly semantic control
A12: sub-03 | B12: LGA44 | C12: 717_LGA44 | D12: 0.55 | E12: 0.13990618 | F12: 717 | G12: aMTG | H12: V | I12: 4
A13: sub-03 | B13: LGA46 | C13: 717_LGA46 | D13: 0.15 | E13: 0.26186146 | F13: 717 | G13: mMTG/STS | H13: V | I13: 46056 | K13: questionable position in image
A14: sub-03 | B14: LGA47 | C14: 717_LGA47 | D14: 0.38 | E14: 0.19501813 | F14: 717 | G14: pMTG | H14: V | I14: 2 | K14: above word area, not clear on position in language streams
A15: sub-03 | B15: LGA9 | C15: 717_LGA9 | D15: 0.8 | E15: 0.14040611 | F15: 717 | G15: aIFG | H15: M | I15: 46211 | K15: a little anterior to Broca, possibly SCN
A16: sub-03 | B16: LGB108 | C16: 717_LGB108 | D16: 1.15 | E16: 0.15948057 | F16: 717 | G16: IFG Broca / Sylvian fissure/ aSTG | H16: M/V | I16: 46206 | K16: pars opercularis
A17: sub-03 | B17: LGB112 | C17: 717_LGB112 | D17: 0.18 | E17: 0.35034977 | F17: 717 | G17: a-mSTG | H17: V | I17: 46056
A18: sub-03 | B18: LGB113 | C18: 717_LGB113 | D18: 0.62 | E18: 0.46300305 | F18: 717 | G18: STS | H18: V/PA | I18: 46054 | K18: a little more towards PA
A19: sub-03 | B19: LGB114 | C19: 717_LGB114 | D19: -0.07 | E19: 0.40928597 | F19: 717 | G19: m-PSTG | H19: PA | I19: 1
A20: sub-03 | B20: LGB116 | C20: 717_LGB116 | D20: 0.43 | E20: 0.28367478 | F20: 717 | G20: a-mMTG | H20: V | I20: 3
A21: sub-03 | B21: LGB117 | C21: 717_LGB117 | D21: 0.48 | E21: 0.24828774 | F21: 717 | G21: mMTG | H21: V | I21: 2
A22: sub-03 | B22: LGB119 | C22: 717_LGB119 | D22: 0.53 | E22: 0.24360204 | F22: 717 | G22: mMTG | H22: V | I22: 2 | K22: In Timna's file looks STS, in MRI looks completely MTG
A23: sub-03 | B23: LGB120 | C23: 717_LGB120 | D23: 0.15 | E23: 0.3133666 | F23: 717 | G23: STG/STS | H23: PA/D/V | I23: 46024 | K23: sul
A24: sub-03 | B24: LGB121 | C24: 717_LGB121 | D24: -0.02 | E24: 0.50232375 | F24: 717 | G24: mMTG/STG | H24: V/PA | I24: 2 | J24: low | K24: weird sulci, possibly wide STG?
A25: sub-03 | B25: LGB122 | C25: 717_LGB122 | D25: 0.18 | E25: 0.31563275 | F25: 717 | G25: mMTG/STG | H25: PA/V | I25: 1 | J25: low
A26: sub-03 | B26: LGB126 | C26: 717_LGB126 | D26: -0.07 | E26: 0.35330649 | F26: 717 | G26: m-pSTS | H26: PA/? | I26: 1 | J26: low
A27: sub-03 | B27: LGB66 | C27: 717_LGB66 | D27: 0.75 | E27: 0.16968604 | F27: 717 | G27: MFG | H27: Out | I27: 15 | K27: SCS?
A28: sub-03 | B28: LGB71 | C28: 717_LGB71 | D28: 0.58 | E28: 0.16961209 | F28: 717 | G28: IFG high | H28: M | I28: 46211 | J28: mid | K28: sulcus above par triangularis
A29: sub-03 | B29: LGB74 | C29: 717_LGB74 | D29: 0.45 | E29: 0.38584152 | F29: 717 | G29: IFG high | H29: M | I29: 7 | J29: mid | K29: pars orbitalis high
A30: sub-03 | B30: LGB75 | C30: 717_LGB75 | D30: 0.3 | E30: 0.26886438 | F30: 717 | G30: IFG Broca high | H30: M | I30: 7 | J30: mid | K30: pars triangularis high
A31: sub-03 | B31: LGB78 | C31: 717_LGB78 | D31: 0.43 | E31: 0.38459759 | F31: 717 | G31: IFG Broca | H31: M | I31: 7 | J31: high
A32: sub-03 | B32: LGB79 | C32: 717_LGB79 | D32: 0.38 | E32: 0.50381211 | F32: 717 | G32: IFG Broca | H32: M | I32: 7 | J32: high
A33: sub-03 | B33: LGB80 | C33: 717_LGB80 | D33: 0.18 | E33: 0.36052651 | F33: 717 | G33: IFG Broca | H33: M | I33: 7 | J33: high
A34: sub-03 | B34: LGB82 | C34: 717_LGB82 | D34: 0.88 | E34: 0.15852163 | F34: 717 | G34: IFG Broca | H34: M | I34: 7 | J34: high
A35: sub-03 | B35: LGB85 | C35: 717_LGB85 | D35: 0.2 | E35: 0.1519181 | F35: 717 | G35: IFG | H35: PM | I35: 9 | J35: mid
A36: sub-03 | B36: LGB86 | C36: 717_LGB86 | D36: 0.3 | E36: 0.28040652 | F36: 717 | G36: IFG | H36: M/PM | I36: 8 | J36: mid | K36: Pars orbitalis
A37: sub-03 | B37: LGB87 | C37: 717_LGB87 | D37: 0.18 | E37: 0.32626836 | F37: 717 | G37: IFG Broca | H37: M | I37: 7 | J37: high | K37: Pars triangularis
A38: sub-03 | B38: LGB88 | C38: 717_LGB88 | D38: 0.95 | E38: 0.24158318 | F38: 717 | G38: IFG Broca | H38: M | I38: 7 | J38: high | K38: Pars triangularis
A39: sub-03 | B39: LGB95 | C39: 717_LGB95 | D39: 0.2 | E39: 0.18218079 | F39: 717 | G39: IFG Broca | H39: M | I39: 46211 | J39: high | K39: close to sulcus
A40: sub-03 | B40: LOF4 | C40: 717_LOF4 | D40: 0.55 | E40: 0.1267815 | F40: 717 | G40: anterior sylvian fissure-orbitofrontal cortex | H40: ? | I40: 46127 | J40: low | K40: low encoding, could be from several regions
...

Sheet NYU to Reg
A1: participant_id | B1: nyu_id | C1: participant_id
A2: sub-01 | B2: 661 | C2: sub-01
A3: sub-02 | B3: 662 | C3: sub-02
A4: sub-03 | B4: 717 | C4: sub-03
A5: sub-04 | B5: 723 | C5: sub-04
A6: sub-05 | B6: 741 | C6: sub-05
A7: sub-06 | B7: 742 | C7: sub-06
A8: sub-07 | B8: 743 | C8: sub-07
A9: sub-08 | B9: 763 | C9: sub-08
A10: sub-09 | B10: 798 | C10: sub-09

Sheet Sheet5
A1: full | B1: NYU sub | C1: sub
A2: NY662_111_Part1_conversation1_EEGPO_02REF | B2: =MID(A2,3,3) -> 662 | C2: =VLOOKUP(B2,'NYU to Reg'!B:C,2) -> sub-02 | D2: =MID(A2,31,80) -> EEGPO_02REF
A3: NY662_111_Part1_conversation1_EEGPO_03REF | B3: =MID(A3,3,3) -> 662 | C3: =VLOOKUP(B3,'NYU to Reg'!B:C,2) -> sub-02 | D3: =MID(A3,31,80) -> EEGPO_03REF
A4: NY717_111_Part1_conversation1_LF6 | B4: =MID(A4,3,3) -> 717 | C4: =VLOOKUP(B4,'NYU to Reg'!B:C,2) -> sub-03 | D4: =MID(A4,31,80) -> LF6
A5: NY717_111_Part1_conversation1_LGA10 | B5: =MID(A5,3,3) -> 717 | C5: =VLOOKUP(B5,'NYU to Reg'!B:C,2) -> sub-03 | D5: =MID(A5,31,80) -> LGA10
A6: NY717_111_Part1_conversation1_LGA11 | B6: =MID(A6,3,3) -> 717 | C6: =VLOOKUP(B6,'NYU to Reg'!B:C,2) -> sub-03 | D6: =MID(A6,31,80) -> LGA11
A7: NY717_111_Part1_conversation1_LGA17 | B7: =MID(A7,3,3) -> 717 | C7: =VLOOKUP(B7,'NYU to Reg'!B:C,2) -> sub-03 | D7: =MID(A7,31,80) -> LGA17
A8: NY717_111_Part1_conversation1_LGA18 | B8: =MID(A8,3,3) -> 717 | C8: =VLOOKUP(B8,'NYU to Reg'!B:C,2) -> sub-03 | D8: =MID(A8,31,80) -> LGA18
A9: NY717_111_Part1_conversation1_LGA19 | B9: =MID(A9,3,3) -> 717 | C9: =VLOOKUP(B9,'NYU to Reg'!B:C,2) -> sub-03 | D9: =MID(A9,31,80) -> LGA19
A10: NY717_111_Part1_conversation1_LGA25 | B10: =MID(A10,3,3) -> 717 | C10: =VLOOKUP(B10,'NYU to Reg'!B:C,2) -> sub-03 | D10: =MID(A10,31,80) -> LGA25
A11: NY717_111_Part1_conversation1_LGA26 | B11: =MID(A11,3,3) -> 717 | C11: =VLOOKUP(B11,'NYU to Reg'!B:C,2) -> sub-03 | D11: =MID(A11,31,80) -> LGA26
A12: NY717_111_Part1_conversation1_LGA27 | B12: =MID(A12,3,3) -> 717 | C12: =VLOOKUP(B12,'NYU to Reg'!B:C,2) -> sub-03 | D12: =MID(A12,31,80) -> LGA27
A13: NY717_111_Part1_conversation1_LGA36 | B13: =MID(A13,3,3) -> 717 | C13: =VLOOKUP(B13,'NYU to Reg'!B:C,2) -> sub-03 | D13: =MID(A13,31,80) -> LGA36
... A209: NY798_111_Part1_conversation1_SF2 | B209: =MID(A209,3,3) -> 798 | C209: =VLOOKUP(B209,'NYU to Reg'!B:C,2) -> sub-09 | D209: =MID(A209,31,80) -> SF2
